Workbook
Name Beginning_Balance: -FV(Guidance!Interest_Rate/12,Guidance!Payment_Number-1,-Guidance!Monthly_Payment,Guidance!Loan_Amount)
Name ColumnTitle1: #NAME?
Name Ending_Balance: -FV(Guidance!Interest_Rate/12,Guidance!Payment_Number,-Guidance!Monthly_Payment,Guidance!Loan_Amount)
Name Header_Row: ROW('[1]Loan Calculator'!$14:$14)
Name Header_Row_Back: ROW('[1]Loan Calculator'!$14:$14)
Name Interest: -IPMT(Guidance!Interest_Rate/12,Guidance!Payment_Number,Guidance!Number_of_Payments,Guidance!Loan_Amount)
Name Interest_Rate: '[1]Loan Calculator'!$E$6
Name Last_Row: IF(Guidance!Values_Entered,Guidance!Header_Row+Guidance!Number_of_Payments,Guidance!Header_Row)
Name Loan_Amount: '[1]Loan Calculator'!$E$5
Name Loan_Not_Paid: IF(Guidance!Payment_Number<=Guidance!Number_of_Payments,1,0)
Name Loan_Start: '[1]Loan Calculator'!$E$8
Name Loan_Years: '[1]Loan Calculator'!$E$7
Name Monthly_Payment: -PMT(Guidance!Interest_Rate/12,Guidance!Number_of_Payments,Guidance!Loan_Amount)
Name Number_of_Payments: '[1]Loan Calculator'!$E$11
Name Payment_Date: DATE(YEAR(Guidance!Loan_Start),MONTH(Guidance!Loan_Start)+Guidance!Payment_Number,DAY(Guidance!Loan_Start))
Name Payment_Number: ROW()-Guidance!Header_Row
Name Principal: -PPMT(Guidance!Interest_Rate/12,Guidance!Payment_Number,Guidance!Number_of_Payments,Guidance!Loan_Amount)
Name Total_Cost: '[1]Loan Calculator'!$E$13
Name Values_Entered: IF(Guidance!Loan_Amount*Guidance!Interest_Rate*Guidance!Loan_Years*Guidance!Loan_Start>0,1,0)
Name Beginning_Balance: -FV(Interest_Rate/12,'1 Business Plan(BP)'!Payment_Number-1,-'1 Business Plan(BP)'!Monthly_Payment,Loan_Amount)
Name ColumnTitle1: #REF!
Name Ending_Balance: -FV(Interest_Rate/12,'1 Business Plan(BP)'!Payment_Number,-'1 Business Plan(BP)'!Monthly_Payment,Loan_Amount)
Name Interest: -IPMT(Interest_Rate/12,'1 Business Plan(BP)'!Payment_Number,Number_of_Payments,Loan_Amount)
Name Last_Row: IF('1 Business Plan(BP)'!Values_Entered,Header_Row+Number_of_Payments,Header_Row)
Name Loan_Not_Paid: IF('1 Business Plan(BP)'!Payment_Number<=Number_of_Payments,1,0)
Name Monthly_Payment: -PMT(Interest_Rate/12,Number_of_Payments,Loan_Amount)
Name Payment_Date: DATE(YEAR(Loan_Start),MONTH(Loan_Start)+'1 Business Plan(BP)'!Payment_Number,DAY(Loan_Start))
Name Payment_Number: ROW()-Header_Row
Name Principal: -PPMT(Interest_Rate/12,'1 Business Plan(BP)'!Payment_Number,Number_of_Payments,Loan_Amount)
Name Values_Entered: IF(Loan_Amount*Interest_Rate*Loan_Years*Loan_Start>0,1,0)
Name Beginning_Balance: -FV('Loan Calculator'!Interest_Rate/12,'Loan Calculator'!Payment_Number-1,-'Loan Calculator'!Monthly_Payment,'Loan Calculator'!Loan_Amount)
Name ColumnTitle1: Loan3[[#Headers],[No.]]
Name Ending_Balance: -FV('Loan Calculator'!Interest_Rate/12,'Loan Calculator'!Payment_Number,-'Loan Calculator'!Monthly_Payment,'Loan Calculator'!Loan_Amount)
Name Full_Print: 'Loan Calculator'!$A$4:$H$262
Name Header_Row: ROW('Loan Calculator'!$26:$26)
Name Header_Row_Back: ROW('Loan Calculator'!$26:$26)
Name Interest: -IPMT('Loan Calculator'!Interest_Rate/12,'Loan Calculator'!Payment_Number,'Loan Calculator'!Number_of_Payments,'Loan Calculator'!Loan_Amount)
Name Interest_Rate: 'Loan Calculator'!$E$18
Name Last_Row: IF('Loan Calculator'!Values_Entered,'Loan Calculator'!Header_Row+'Loan Calculator'!Number_of_Payments,'Loan Calculator'!Header_Row)
Name Loan_Amount: 'Loan Calculator'!$E$17
Name Loan_Not_Paid: IF('Loan Calculator'!Payment_Number<='Loan Calculator'!Number_of_Payments,1,0)
Name Loan_Start: 'Loan Calculator'!$E$20
Name Loan_Years: 'Loan Calculator'!$E$19
Name Monthly_Payment: -PMT('Loan Calculator'!Interest_Rate/12,'Loan Calculator'!Number_of_Payments,'Loan Calculator'!Loan_Amount)
Name Number_of_Payments: 'Loan Calculator'!$E$22
Name Payment_Date: DATE(YEAR('Loan Calculator'!Loan_Start),MONTH('Loan Calculator'!Loan_Start)+'Loan Calculator'!Payment_Number,DAY('Loan Calculator'!Loan_Start))
Name Payment_Number: ROW()-'Loan Calculator'!Header_Row
Name Principal: -PPMT('Loan Calculator'!Interest_Rate/12,'Loan Calculator'!Payment_Number,'Loan Calculator'!Number_of_Payments,'Loan Calculator'!Loan_Amount)
Name Print_Titles: 'Loan Calculator'!$26:$26
Name RowTitleRegion1..E6: 'Loan Calculator'!$B$17
Name RowTitleRegion2..E11: 'Loan Calculator'!$B$22
Name Total_Cost: 'Loan Calculator'!$E$24
Name Total_Interest: 'Loan Calculator'!$E$23
Name Values_Entered: IF('Loan Calculator'!Loan_Amount*'Loan Calculator'!Interest_Rate*'Loan Calculator'!Loan_Years*'Loan Calculator'!Loan_Start>0,1,0)
Name Beginning_Balance: -FV('Excel Tips'!Interest_Rate/12,'Excel Tips'!Payment_Number-1,-'Excel Tips'!Monthly_Payment,'Excel Tips'!Loan_Amount)
Name ColumnTitle1: #NAME?
Name Ending_Balance: -FV('Excel Tips'!Interest_Rate/12,'Excel Tips'!Payment_Number,-'Excel Tips'!Monthly_Payment,'Excel Tips'!Loan_Amount)
Name Header_Row: ROW('[1]Loan Calculator'!$14:$14)
Name Header_Row_Back: ROW('[1]Loan Calculator'!$14:$14)
Name Interest: -IPMT('Excel Tips'!Interest_Rate/12,'Excel Tips'!Payment_Number,'Excel Tips'!Number_of_Payments,'Excel Tips'!Loan_Amount)

Sheet Months
A1: January
A2: February
A3: March
A4: April
A5: May
A6: June
A7: July
A8: August
A9: September
A10: October
A11: November
A12: December

Sheet Guidance
D3: Name:
D4: Company Name:
B6: Guidance on using these templates for your Start Up Loan application
B7: - First, please save your name and company name to this document, using the space above - In this document, you will find four tabs, that need to be completed as part of your loan application - Don't worry if you need some help. At the top of each tab you will find both a description of each of the templates, as well as some tips on how to complete them - We suggest you complete each template in number order so that you can carry forward any of your workings - If you need some help completing these documents, you can submit them as a first draft, within the customer portal and one of our Business Support Partners will be in touch to provide further assistance - If you have already completed a Business Plan, Personal Survival Budget or Cash Flow Forecast, you do not have to transfer the information into our templates - Our templates have been designed to support our application process, so we would encourage you to provide the information we have requested across these templates, to help us assess your application quicker, so please review the information you provide before submitting - Finally, don't forget to save your document as you go through
B10: TIPS ON COMPLETING THE TEMPLATES
B12: * | C12: The templates are designed to be as easy to use as possible - for the BP tab, please follow the guidelines closely and relate these guidelines to your business. For the CFF, SA and PSB, simply enter your figures into the white coloured cells on the templates and all of the light blue coloured cells will auto-calculate based on your responses.
B13: * | C13: For an explanation of any terms included on these templates, hover over the cells that have a red triangle in the top right corner and you will see some further instructions and guidance related to that item. If you're still unsure don't worry: your first draft won't necessarily be your final submission. Your Business Adviser will be able to work with you once you have submitted an initial draft;
B14: * | C14: For the PSB and CFF, If you want to see what formula is being used to calculate any of the blue cells, or find out which cells are being used in the calculation, simply click on the cell and the formula will display in the Formula Bar at the top of the page;
B15: * | C15: If any of the numbers you enter result in a negative balance, then this negative balance will be displayed in red to draw this to your attention. Ideally, you want to avoid negative totals or balances, so think about what you can feasibly change in order to achieve this. Alternatively please provide details of how this negative balance will be covered (i.e. Business overdraft etc.) within the commentary box provided;
B16: * | C16: The templates list a range of common options but they might not all be applicable for you. Add or remove items as relevant to you and your business;
B17: * | C17: All values that you enter should be in GBP (£) and should include VAT;
B18: * | C18: Use the commentary box at the bottom of the templates to explain any assumptions you've made or notes you'd like to discuss with your Business Adviser;
B20: * | C20: For free and impartial advice on your personal budgeting, contact the government-backed Money Advice Service via their website or telephone.
C21: Go to http://www.moneyadviceservice.org.uk or call: 0800 138 7777 (calls are free).
B23: Excel Tips
B25: * | C25: If you need to go to the next line in a cell or create another bullet point in the same cell, press and hold the Alt key and click the Enter key once. This will tab down to the next line but you will remain in the same cell. To save the changes you have made to the cell, press Enter once you are finished. Do not press Esc as this will delete your changes.
B26: * | C26: If you need to edit a cell without deleting any of the text you have already typed in, first select the cell and click in the formula bar (shown in screenshot below)
B27: * | C27: If you need more help with using excel please see our Excel Tips tab
B29: Uploading this document to the portal
B31: * | C31: Once you reach Stage 3:1 in the online application process you will first be asked to provide some basic information about your business as shown below (left)
B32: * | C32: Following this, you will reach stage 3:2 where you will be asked to upload your business documents as shown below (right). You will also have the option to request help with your documents, if you need it.
C34: Stage 3:1 | J34: Stage 3:2
B60: * | C60: If you need to re-visit the portal and re-upload your documents after making amendments, you can do so at any time by logging into your account and viewing the "Your Business information and documents" section on the portal and re-uploading.

Sheet 1 Business Plan(BP)
B3: Business Plan
D4: Name: | E4: Lauren Keenan
D5: Company Name: | E5: DefaultCompany
B7: Your Business Plan (BP) should detail your blueprint for how your business will operate. Your Business Plan is designed to help us determine whether or not your Business is viable and can sustainably produce sufficient profits to maintain your monthly Start Up Loan repayments.
B9: - The content in the Business Plan below is the minimum requirement for completing the business viability part of your application;
B10: - Please complete each field using the questions, prompts and examples as a guideline for the detail that we require;
B11: - The closer you can follow the guidelines to complete the BP, the more likely you are to provide your assigned Business Support Partner with the information they need to make a decision;
B12: - In some instances, more information may be required. If this is the case, your Business Adviser will inform you of what further information is needed;
B13: - Please note, your BP can be a first draft, it doesn't have to be perfect. If you need more help, submit what you can and your Business Support Partner will be in touch;
B15: 1. Your business and objectives | K15: Guidance
B18: Describe your business, outlining the different product(s) and/or service(s) you offer:
B19: TheTeam is a small software firm (1-10) providing an app tracking software that can be used as a digital wellness tool. The software aims to silently track user screen time of social media applications and translate their minutes of use into grams of CO2 equivalent (CO2eq) to reflect the emissions generated by their usage. The CO2eq is then cross referenced with a database of CO2 sink events found in the natural world, and a comparison between the digital activity of the user and a natural world event is created and offered back to the user as a means to better contextualise an otherwise non-physical activity. A greater objective of the software is to reintroduce an awareness of the natural world and our individual place within it, utlimately benefitting our own health by encouraging reduced screen time, empowering users as conscientious and informed consumers, and hopefully encouraging a sense of stewardship towards the enviroment. The application should also log users decreased screen time in CO2eq, allowing the user to work towards a goal of "Xg" equivalent to trees planted by local forestry and sustainability students within The University of the Highlands and Islands (UHI). The project lead owns 90% of the company, with 5% belonging to the organization I work for (the University of the Highlands and Islands) and the remaining shares belonging to team members. The business is not yet trading. The operational structure consists of 3 primary executive consultants (teaching staff), myself as project lead and 2 additional members of the development team. This is a home based business without Commercial Premises. Key Milestones achieved thus far are the project's first release, built for production and ready for distribution. As of yet there are no purchase orders.
B38: Objectives:
B40: Short term (current year):
B41: The application will be deployed through an industry-standard Continuous Integration/Continuous Development (CICD) pipeline to deliver releases from early in the project by Oct '24 First software release achieved: Create an application that uses Augmented Reality (AR) and Artificial Intelligence (AI) to present a 3D Avatar when a physical image is scanned by the users phone by Dec '24. Reduce software dependency costs significantly by using external data sources responsibly by Dec '24
B48: Medium term (next 1 – 2 years):
B49: Second development release is achieved: Connect the end user directly to the card-issuers LinkedIn data via a layer of AR and AI which adds a visual and audio event to the business card by Feb '25 Soft launch the product on LinkedIn and social medias to stoke user interest by Apr '25 Update social media with significant development milestones or with teasers for features under development, gauge audience sentiments by Apr '25 Third development release is achieved: End-user can contact card-issuer through application by May '25 Send a service quality survey to every customer within 20 days of their first contact by May '25
B56: Your Start Up Loan:
B58: Describe how you will use your Start Up Loan and how it will help you achieve these objectives:
B59: Cost Description | E59: Cost (£) | F59: Rationale
B60: Development manpower | E60: 1000 | F60: Developers need to be paid
B61: Dedicated support team | E61: 500 | F61: Appication must have a support team to handle customer issues
B62: Higher tier of ProxyCurl API | E62: 500 | F62: As product scales, data traffic will need to be supported
B63: Higher tier of WatsonX API | E63: 500 | F63: As product scales, WatsonX requests will need to be supported
B73: 2. Your skills and experience
B76: Outline any previous experience, employment or other work that you have done that is relevant to your business:
B77: 4 years of experience developing a range of different softwares in different Agile development teams. Previously have contributed to a startup software. Currently working closely with a startup business, leading the development of a commercial/research software project in industry. I am a creative, a natural communicator and problem solver who is successful at incentivising the teams I work in.
B84: Outline any education or training you have had that is relevant to your business:
B85: I have 5 years of experience in various trainings and educations for programming and software development. I am an associates-level python programmer both PCEP and PCAP certified by Cisco and the Open University. I have achieved my base degree of the University of the Highlands and Islands Applied Software Development Bsc and am currently working to achieve the Honours portion of the degree.
B94: 3. Your target customers | L94: Guidance
B97: Demographic details:
B98: Briefly describe your target customers:
B99: Current expected customer base is primarily Job seekers, but also recruiters and employers Likely within the tech industry, likely jobseekers between ages 16-34s (Ipsos, 2024) The technology is likely to be used by demographics that already use physical business cards and also show interest in digital business cards. Psychographics of ages 16-34s show a significant increase in consumption of digital media, with 79% of commercial media consumed by the age group being digital, and time spent with online video media up 236% from 2015 to 2020. (Navigate Video, 2024) These findings cement this demographic as our main target audience, to adopt the shift from traditional to digital business card model.
B105: What customer need or problem does your product(s) and/or service(s) address?
B106: Job markets are oversaturated, and business cards are a traditional technology losing relevance in an increasingly digitized world. Job seekers need to stand out from their competition and remain in employers minds during the recruitment process. This can be achieved by use of an emerging media that can modernise the traditional business card model and make professional interactions more memorable by using AR and AI to add a 3D and audio layer to the experience, bringing an old technology into the present and giving customers an edge to their professional profile.
B112: Explain your approach to pricing your product(s) and/or service(s):
B113: The application will be accessible through a one-off minimal charge of £0.50 that will cover costs of the apps use for that user, and give the customer access to all following updates issued to maintain the software. Should external dependency charges increase to use the application, the user will be notified and given the opportunity to pay another standalone charge to continue to use up-to-date data in the app.
B121: 4. Your market and competition | L121: Guidance
B124: What research have you conducted to understand your market, including your industry, regions, customers, competitors?
B125: Delete any answers not applicable to you and provide some description as relevant.
...

Sheet Loan Calculator
B3: Loan calculator
B5: INSTRUCTIONS Only complete fields E10, E12 and E13. If you have a Capital Repayment Holiday, complete the Capital Repayment section. 1. Fill in loan value 2. Fill in loan term 3. All other fields will automatically populate 4. Scroll down to the table below to see the repayments after the CRH. 5. Go to the CFF (tab below) 6. Loan repayment row on the CFF has been automatically populated.
B10: Key:
B16: Enter values | G16: Capital Repayment Holiday
B17: Loan amount | E17: 7000 | G17: Do you have a CRH?
B18: Annual interest rate | E18: 0.06 | G18: No | K18: Yes
B19: Loan period in months | E19: 60 | G19: =IF(ISBLANK(G18),"",IF(G18="Yes","Length of CRH (Months)","Please enter loan values")) -> Please enter loan values | K19: No
B20: =IF(G18="Yes","Start date of loan after CRH","Start date of loan") -> Start date of loan | E20: 44145 | G20: 6
B21: Monthly payment | E21: =IFERROR(IF(Values_Entered,Monthly_Payment,""), "") -> 135.32961 | G21: =IF(ISBLANK(G20),"","Start date of loan") -> Start date of loan
B22: Number of payments | E22: =IFERROR(IF(Values_Entered,Loan_Years,""), "") -> 60 | G22: 44277
B23: Total interest | E23: =IFERROR(IF(Values_Entered,Total_Cost-Loan_Amount,""), "") -> 1119.7766 | G23: Payment for CRH Period
B24: Total cost of loan | E24: =IFERROR(IF(Values_Entered,Monthly_Payment*Number_of_Payments,""), "") -> 8119.7766 | G24: =IF(ISBLANK(G20),"",G27) -> 35
B26: No. | C26: Payment Date | D26: Beginning Balance | E26: Payment | F26: Principal | G26: Interest | H26: Ending Balance
B27: =IFERROR(IF(Loan_Not_Paid*Values_Entered,Payment_Number,""), "") -> 1 | C27: =IFERROR(IF(Loan_Not_Paid*Values_Entered,Payment_Date,""), "") -> 44175 | D27: =IFERROR(IF(Loan_Not_Paid*Values_Entered,Beginning_Balance,""), "") -> 7000 | E27: =IFERROR(IF(Loan_Not_Paid*Values_Entered,Monthly_Payment,""), "") -> 135.32961 | F27: =IFERROR(IF(Loan_Not_Paid*Values_Entered,Principal,""), "") -> 100.32961 | G27: =IFERROR(IF(Loan_Not_Paid*Values_Entered,Interest,""), "") -> 35 | H27: =IFERROR(IF(Loan_Not_Paid*Values_Entered,Ending_Balance,""), "") -> 6899.6704
B28: =IFERROR(IF(Loan_Not_Paid*Values_Entered,Payment_Number,""), "") -> 2 | C28: =IFERROR(IF(Loan_Not_Paid*Values_Entered,Payment_Date,""), "") -> 44206 | D28: =IFERROR(IF(Loan_Not_Paid*Values_Entered,Beginning_Balance,""), "") -> 6899.6704 | E28: =IFERROR(IF(Loan_Not_Paid*Values_Entered,Monthly_Payment,""), "") -> 135.32961 | F28: =IFERROR(IF(Loan_Not_Paid*Values_Entered,Principal,""), "") -> 100.83126 | G28: =IFERROR(IF(Loan_Not_Paid*Values_Entered,Interest,""), "") -> 34.498352 | H28: =IFERROR(IF(Loan_Not_Paid*Values_Entered,Ending_Balance,""), "") -> 6798.8391
B29: =IFERROR(IF(Loan_Not_Paid*Values_Entered,Payment_Number,""), "") -> 3 | C29: =IFERROR(IF(Loan_Not_Paid*Values_Entered,Payment_Date,""), "") -> 44237 | D29: =IFERROR(IF(Loan_Not_Paid*Values_Entered,Beginning_Balance,""), "") -> 6798.8391 | E29: =IFERROR(IF(Loan_Not_Paid*Values_Entered,Monthly_Payment,""), "") -> 135.32961 | F29: =IFERROR(IF(Loan_Not_Paid*Values_Entered,Principal,""), "") -> 101.33542 | G29: =IFERROR(IF(Loan_Not_Paid*Values_Entered,Interest,""), "") -> 33.994196 | H29: =IFERROR(IF(Loan_Not_Paid*Values_Entered,Ending_Balance,""), "") -> 6697.5037
B30: =IFERROR(IF(Loan_Not_Paid*Values_Entered,Payment_Number,""), "") -> 4 | C30: =IFERROR(IF(Loan_Not_Paid*Values_Entered,Payment_Date,""), "") -> 44265 | D30: =IFERROR(IF(Loan_Not_Paid*Values_Entered,Beginning_Balance,""), "") -> 6697.5037 | E30: =IFERROR(IF(Loan_Not_Paid*Values_Entered,Monthly_Payment,""), "") -> 135.32961 | F30: =IFERROR(IF(Loan_Not_Paid*Values_Entered,Principal,""), "") -> 101.84209 | G30: =IFERROR(IF(Loan_Not_Paid*Values_Entered,Interest,""), "") -> 33.487519 | H30: =IFERROR(IF(Loan_Not_Paid*Values_Entered,Ending_Balance,""), "") -> 6595.6616
B31: =IFERROR(IF(Loan_Not_Paid*Values_Entered,Payment_Number,""), "") -> 5 | C31: =IFERROR(IF(Loan_Not_Paid*Values_Entered,Payment_Date,""), "") -> 44296 | D31: =IFERROR(IF(Loan_Not_Paid*Values_Entered,Beginning_Balance,""), "") -> 6595.6616 | E31: =IFERROR(IF(Loan_Not_Paid*Values_Entered,Monthly_Payment,""), "") -> 135.32961 | F31: =IFERROR(IF(Loan_Not_Paid*Values_Entered,Principal,""), "") -> 102.3513 | G31: =IFERROR(IF(Loan_Not_Paid*Values_Entered,Interest,""), "") -> 32.978308 | H31: =IFERROR(IF(Loan_Not_Paid*Values_Entered,Ending_Balance,""), "") -> 6493.3103
B32: =IFERROR(IF(Loan_Not_Paid*Values_Entered,Payment_Number,""), "") -> 6 | C32: =IFERROR(IF(Loan_Not_Paid*Values_Entered,Payment_Date,""), "") -> 44326 | D32: =IFERROR(IF(Loan_Not_Paid*Values_Entered,Beginning_Balance,""), "") -> 6493.3103 | E32: =IFERROR(IF(Loan_Not_Paid*Values_Entered,Monthly_Payment,""), "") -> 135.32961 | F32: =IFERROR(IF(Loan_Not_Paid*Values_Entered,Principal,""), "") -> 102.86306 | G32: =IFERROR(IF(Loan_Not_Paid*Values_Entered,Interest,""), "") -> 32.466552 | H32: =IFERROR(IF(Loan_Not_Paid*Values_Entered,Ending_Balance,""), "") -> 6390.4473
B33: =IFERROR(IF(Loan_Not_Paid*Values_Entered,Payment_Number,""), "") -> 7 | C33: =IFERROR(IF(Loan_Not_Paid*Values_Entered,Payment_Date,""), "") -> 44357 | D33: =IFERROR(IF(Loan_Not_Paid*Values_Entered,Beginning_Balance,""), "") -> 6390.4473 | E33: =IFERROR(IF(Loan_Not_Paid*Values_Entered,Monthly_Payment,""), "") -> 135.32961 | F33: =IFERROR(IF(Loan_Not_Paid*Values_Entered,Principal,""), "") -> 103.37737 | G33: =IFERROR(IF(Loan_Not_Paid*Values_Entered,Interest,""), "") -> 31.952236 | H33: =IFERROR(IF(Loan_Not_Paid*Values_Entered,Ending_Balance,""), "") -> 6287.0699
B34: =IFERROR(IF(Loan_Not_Paid*Values_Entered,Payment_Number,""), "") -> 8 | C34: =IFERROR(IF(Loan_Not_Paid*Values_Entered,Payment_Date,""), "") -> 44387 | D34: =IFERROR(IF(Loan_Not_Paid*Values_Entered,Beginning_Balance,""), "") -> 6287.0699 | E34: =IFERROR(IF(Loan_Not_Paid*Values_Entered,Monthly_Payment,""), "") -> 135.32961 | F34: =IFERROR(IF(Loan_Not_Paid*Values_Entered,Principal,""), "") -> 103.89426 | G34: =IFERROR(IF(Loan_Not_Paid*Values_Entered,Interest,""), "") -> 31.435349 | H34: =IFERROR(IF(Loan_Not_Paid*Values_Entered,Ending_Balance,""), "") -> 6183.1756
B35: =IFERROR(IF(Loan_Not_Paid*Values_Entered,Payment_Number,""), "") -> 9 | C35: =IFERROR(IF(Loan_Not_Paid*Values_Entered,Payment_Date,""), "") -> 44418 | D35: =IFERROR(IF(Loan_Not_Paid*Values_Entered,Beginning_Balance,""), "") -> 6183.1756 | E35: =IFERROR(IF(Loan_Not_Paid*Values_Entered,Monthly_Payment,""), "") -> 135.32961 | F35: =IFERROR(IF(Loan_Not_Paid*Values_Entered,Principal,""), "") -> 104.41373 | G35: =IFERROR(IF(Loan_Not_Paid*Values_Entered,Interest,""), "") -> 30.915878 | H35: =IFERROR(IF(Loan_Not_Paid*Values_Entered,Ending_Balance,""), "") -> 6078.7619
B36: =IFERROR(IF(Loan_Not_Paid*Values_Entered,Payment_Number,""), "") -> 10 | C36: =IFERROR(IF(Loan_Not_Paid*Values_Entered,Payment_Date,""), "") -> 44449 | D36: =IFERROR(IF(Loan_Not_Paid*Values_Entered,Beginning_Balance,""), "") -> 6078.7619 | E36: =IFERROR(IF(Loan_Not_Paid*Values_Entered,Monthly_Payment,""), "") -> 135.32961 | F36: =IFERROR(IF(Loan_Not_Paid*Values_Entered,Principal,""), "") -> 104.9358 | G36: =IFERROR(IF(Loan_Not_Paid*Values_Entered,Interest,""), "") -> 30.393809 | H36: =IFERROR(IF(Loan_Not_Paid*Values_Entered,Ending_Balance,""), "") -> 5973.8261
B37: =IFERROR(IF(Loan_Not_Paid*Values_Entered,Payment_Number,""), "") -> 11 | C37: =IFERROR(IF(Loan_Not_Paid*Values_Entered,Payment_Date,""), "") -> 44479 | D37: =IFERROR(IF(Loan_Not_Paid*Values_Entered,Beginning_Balance,""), "") -> 5973.8261 | E37: =IFERROR(IF(Loan_Not_Paid*Values_Entered,Monthly_Payment,""), "") -> 135.32961 | F37: =IFERROR(IF(Loan_Not_Paid*Values_Entered,Principal,""), "") -> 105.46048 | G37: =IFERROR(IF(Loan_Not_Paid*Values_Entered,Interest,""), "") -> 29.86913 | H37: =IFERROR(IF(Loan_Not_Paid*Values_Entered,Ending_Balance,""), "") -> 5868.3656
B38: =IFERROR(IF(Loan_Not_Paid*Values_Entered,Payment_Number,""), "") -> 12 | C38: =IFERROR(IF(Loan_Not_Paid*Values_Entered,Payment_Date,""), "") -> 44510 | D38: =IFERROR(IF(Loan_Not_Paid*Values_Entered,Beginning_Balance,""), "") -> 5868.3656 | E38: =IFERROR(IF(Loan_Not_Paid*Values_Entered,Monthly_Payment,""), "") -> 135.32961 | F38: =IFERROR(IF(Loan_Not_Paid*Values_Entered,Principal,""), "") -> 105.98778 | G38: =IFERROR(IF(Loan_Not_Paid*Values_Entered,Interest,""), "") -> 29.341828 | H38: =IFERROR(IF(Loan_Not_Paid*Values_Entered,Ending_Balance,""), "") -> 5762.3778
... B90: =IFERROR(IF(Loan_Not_Paid*Values_Entered,Payment_Number,""), "") | C90: =IFERROR(IF(Loan_Not_Paid*Values_Entered,Payment_Date,""), "") | D90: =IFERROR(IF(Loan_Not_Paid*Values_Entered,Beginning_Balance,""), "") | E90: =IFERROR(IF(Loan_Not_Paid*Values_Entered,Monthly_Payment,""), "") | F90: =IFERROR(IF(Loan_Not_Paid*Values_Entered,Principal,""), "") | G90: =IFERROR(IF(Loan_Not_Paid*Values_Entered,Interest,""), "") | H90: =IFERROR(IF(Loan_Not_Paid*Values_Entered,Ending_Balance,""), "")
B91: =IFERROR(IF(Loan_Not_Paid*Values_Entered,Payment_Number,""),"") | C91: =IFERROR(IF(Loan_Not_Paid*Values_Entered,Payment_Date,""),"") | D91: =IFERROR(IF(Loan_Not_Paid*Values_Entered,Beginning_Balance,""),"") | E91: =IFERROR(IF(Loan_Not_Paid*Values_Entered,Monthly_Payment,""),"") | F91: =IFERROR(IF(Loan_Not_Paid*Values_Entered,Principal,""),"") | G91: =IFERROR(IF(Loan_Not_Paid*Values_Entered,Interest,""),"") | H91: =IFERROR(IF(Loan_Not_Paid*Values_Entered,Ending_Balance,""),"")
B92: =IFERROR(IF(Loan_Not_Paid*Values_Entered,Payment_Number,""),"") | C92: =IFERROR(IF(Loan_Not_Paid*Values_Entered,Payment_Date,""),"") | D92: =IFERROR(IF(Loan_Not_Paid*Values_Entered,Beginning_Balance,""),"") | E92: =IFERROR(IF(Loan_Not_Paid*Values_Entered,Monthly_Payment,""),"") | F92: =IFERROR(IF(Loan_Not_Paid*Values_Entered,Principal,""),"") | G92: =IFERROR(IF(Loan_Not_Paid*Values_Entered,Interest,""),"") | H92: =IFERROR(IF(Loan_Not_Paid*Values_Entered,Ending_Balance,""),"")
B93: =IFERROR(IF(Loan_Not_Paid*Values_Entered,Payment_Number,""),"") | C93: =IFERROR(IF(Loan_Not_Paid*Values_Entered,Payment_Date,""),"") | D93: =IFERROR(IF(Loan_Not_Paid*Values_Entered,Beginning_Balance,""),"") | E93: =IFERROR(IF(Loan_Not_Paid*Values_Entered,Monthly_Payment,""),"") | F93: =IFERROR(IF(Loan_Not_Paid*Values_Entered,Principal,""),"") | G93: =IFERROR(IF(Loan_Not_Paid*Values_Entered,Interest,""),"") | H93: =IFERROR(IF(Loan_Not_Paid*Values_Entered,Ending_Balance,""),"")
B94: =IFERROR(IF(Loan_Not_Paid*Values_Entered,Payment_Number,""),"") | C94: =IFERROR(IF(Loan_Not_Paid*Values_Entered,Payment_Date,""),"") | D94: =IFERROR(IF(Loan_Not_Paid*Values_Entered,Beginning_Balance,""),"") | E94: =IFERROR(IF(Loan_Not_Paid*Values_Entered,Monthly_Payment,""),"") | F94: =IFERROR(IF(Loan_Not_Paid*Values_Entered,Principal,""),"") | G94: =IFERROR(IF(Loan_Not_Paid*Values_Entered,Interest,""),"") | H94: =IFERROR(IF(Loan_Not_Paid*Values_Entered,Ending_Balance,""),"")
B95: =IFERROR(IF(Loan_Not_Paid*Values_Entered,Payment_Number,""),"") | C95: =IFERROR(IF(Loan_Not_Paid*Values_Entered,Payment_Date,""),"") | D95: =IFERROR(IF(Loan_Not_Paid*Values_Entered,Beginning_Balance,""),"") | E95: =IFERROR(IF(Loan_Not_Paid*Values_Entered,Monthly_Payment,""),"") | F95: =IFERROR(IF(Loan_Not_Paid*Values_Entered,Principal,""),"") | G95: =IFERROR(IF(Loan_Not_Paid*Values_Entered,Interest,""),"") | H95: =IFERROR(IF(Loan_Not_Paid*Values_Entered,Ending_Balance,""),"")
B96: =IFERROR(IF(Loan_Not_Paid*Values_Entered,Payment_Number,""),"") | C96: =IFERROR(IF(Loan_Not_Paid*Values_Entered,Payment_Date,""),"") | D96: =IFERROR(IF(Loan_Not_Paid*Values_Entered,Beginning_Balance,""),"") | E96: =IFERROR(IF(Loan_Not_Paid*Values_Entered,Monthly_Payment,""),"") | F96: =IFERROR(IF(Loan_Not_Paid*Values_Entered,Principal,""),"") | G96: =IFERROR(IF(Loan_Not_Paid*Values_Entered,Interest,""),"") | H96: =IFERROR(IF(Loan_Not_Paid*Values_Entered,Ending_Balance,""),"")
B97: =IFERROR(IF(Loan_Not_Paid*Values_Entered,Payment_Number,""),"") | C97: =IFERROR(IF(Loan_Not_Paid*Values_Entered,Payment_Date,""),"") | D97: =IFERROR(IF(Loan_Not_Paid*Values_Entered,Beginning_Balance,""),"") | E97: =IFERROR(IF(Loan_Not_Paid*Values_Entered,Monthly_Payment,""),"") | F97: =IFERROR(IF(Loan_Not_Paid*Values_Entered,Principal,""),"") | G97: =IFERROR(IF(Loan_Not_Paid*Values_Entered,Interest,""),"") | H97: =IFERROR(IF(Loan_Not_Paid*Values_Entered,Ending_Balance,""),"")
B98: =IFERROR(IF(Loan_Not_Paid*Values_Entered,Payment_Number,""),"") | C98: =IFERROR(IF(Loan_Not_Paid*Values_Entered,Payment_Date,""),"") | D98: =IFERROR(IF(Loan_Not_Paid*Values_Entered,Beginning_Balance,""),"") | E98: =IFERROR(IF(Loan_Not_Paid*Values_Entered,Monthly_Payment,""),"") | F98: =IFERROR(IF(Loan_Not_Paid*Values_Entered,Principal,""),"") | G98: =IFERROR(IF(Loan_Not_Paid*Values_Entered,Interest,""),"") | H98: =IFERROR(IF(Loan_Not_Paid*Values_Entered,Ending_Balance,""),"")
B99: =IFERROR(IF(Loan_Not_Paid*Values_Entered,Payment_Number,""),"") | C99: =IFERROR(IF(Loan_Not_Paid*Values_Entered,Payment_Date,""),"") | D99: =IFERROR(IF(Loan_Not_Paid*Values_Entered,Beginning_Balance,""),"") | E99: =IFERROR(IF(Loan_Not_Paid*Values_Entered,Monthly_Payment,""),"") | F99: =IFERROR(IF(Loan_Not_Paid*Values_Entered,Principal,""),"") | G99: =IFERROR(IF(Loan_Not_Paid*Values_Entered,Interest,""),"") | H99: =IFERROR(IF(Loan_Not_Paid*Values_Entered,Ending_Balance,""),"")
B100: =IFERROR(IF(Loan_Not_Paid*Values_Entered,Payment_Number,""),"") | C100: =IFERROR(IF(Loan_Not_Paid*Values_Entered,Payment_Date,""),"") | D100: =IFERROR(IF(Loan_Not_Paid*Values_Entered,Beginning_Balance,""),"") | E100: =IFERROR(IF(Loan_Not_Paid*Values_Entered,Monthly_Payment,""),"") | F100: =IFERROR(IF(Loan_Not_Paid*Values_Entered,Principal,""),"") | G100: =IFERROR(IF(Loan_Not_Paid*Values_Entered,Interest,""),"") | H100: =IFERROR(IF(Loan_Not_Paid*Values_Entered,Ending_Balance,""),"")
B101: =IFERROR(IF(Loan_Not_Paid*Values_Entered,Payment_Number,""),"") | C101: =IFERROR(IF(Loan_Not_Paid*Values_Entered,Payment_Date,""),"") | D101: =IFERROR(IF(Loan_Not_Paid*Values_Entered,Beginning_Balance,""),"") | E101: =IFERROR(IF(Loan_Not_Paid*Values_Entered,Monthly_Payment,""),"") | F101: =IFERROR(IF(Loan_Not_Paid*Values_Entered,Principal,""),"") | G101: =IFERROR(IF(Loan_Not_Paid*Values_Entered,Interest,""),"") | H101: =IFERROR(IF(Loan_Not_Paid*Values_Entered,Ending_Balance,""),"")
B102: =IFERROR(IF(Loan_Not_Paid*Values_Entered,Payment_Number,""),"") | C102: =IFERROR(IF(Loan_Not_Paid*Values_Entered,Payment_Date,""),"") | D102: =IFERROR(IF(Loan_Not_Paid*Values_Entered,Beginning_Balance,""),"") | E102: =IFERROR(IF(Loan_Not_Paid*Values_Entered,Monthly_Payment,""),"") | F102: =IFERROR(IF(Loan_Not_Paid*Values_Entered,Principal,""),"") | G102: =IFERROR(IF(Loan_Not_Paid*Values_Entered,Interest,""),"") | H102: =IFERROR(IF(Loan_Not_Paid*Values_Entered,Ending_Balance,""),"")
... B262: =IFERROR(IF(Loan_Not_Paid*Values_Entered,Payment_Number,""),"") | C262: =IFERROR(IF(Loan_Not_Paid*Values_Entered,Payment_Date,""),"") | D262: =IFERROR(IF(Loan_Not_Paid*Values_Entered,Beginning_Balance,""),"") | E262: =IFERROR(IF(Loan_Not_Paid*Values_Entered,Monthly_Payment,""),"") | F262: =IFERROR(IF(Loan_Not_Paid*Values_Entered,Principal,""),"") | G262: =IFERROR(IF(Loan_Not_Paid*Values_Entered,Interest,""),"") | H262: =IFERROR(IF(Loan_Not_Paid*Values_Entered,Ending_Balance,""),"")

Sheet 4 Cash Flow Forecast(CFF) (2)
B3: 12-Month Cash Flow Forecast
B5: Name: | C5: =IF(ISBLANK(Guidance!$E$3),"",Guidance!$E$3)
B6: Company Name: | C6: =IF(ISBLANK(Guidance!$E$4),"",Guidance!$E$4)
B8: Your Cash Flow Forecast (CFF) is an estimate of the money you expect to bring in to and pay out of your business over the next 12-months. Importantly, it should reflect all of the activity you have described in your Business Plan. - Your CFF should show BUSINESS revenue and expenses only, not personal items; - Your CFF is FORWARD looking, reflecting future anticipated transactions into and out of your business; - You can input your loan amount and the term length (12-60months), which will autocalculate onto the CFF below; - You will be asked to choose a start month for your CFF; this should be the next month after you expect to receive the loan and should match up with the month you selected in your Sales Assumptions; - Remember, some of the information that you have created in your Sales Assumptions will auto-populate in your CFF tab. These cells are blue and you do not need to edit them; - Any assumptions you make regarding your cash in-flows and cash out-flows should be both realistic and supportable. If you're starting a new business, we suggest being conservative with the cash flows you enter for the early months of trading; - It's important that your CFF corresponds with all of the objectives and activities you have outlined in your Business Plan. For example, if you have detailed plans for a three-month marketing campaign in your Business Plan then the costs for running this campaign should be clearly visible in your CFF; - Your CFF is based on a future estimate and while these figures will no doubt change over that trading period, it is a good amount of time for you - and us - to see how sustainable your plans are; - There is a commentary box at the bottom, for which you can use to explain any of costings, which you think will be of use to your Business Adviser
O13: Key:
P14: These cells auto-calculate - you don't need to edit these.
P15: Insert your own text/numbers into these cells as relevant.
B18: Loan amount | C18: 2500
B19: Interest rate | C19: 0.06
B20: Loan term (months) | C20: 0
B21: Monthly repayment | C21: =IFERROR(PMT(C19/12,C20,C18)*-1,"")
B23: Select your starting month: | C23: May
E24: MONTHS
B25: Cash in-flows | C25: Description (as required) | D25: Starting point | E25: 1 | F25: 2 | G25: 3 | H25: 4 | I25: 5 | J25: 6 | K25: 7 | L25: 8 | M25: 9 | N25: 10 | O25: 11 | P25: 12 | Q25: TOTAL
B26: Total anticipated sales | D26: 0 | E26: =#REF! -> #REF! | F26: =#REF! -> #REF! | G26: =#REF! -> #REF! | H26: =#REF! -> #REF! | I26: =#REF! -> #REF! | J26: =#REF! -> #REF! | K26: =#REF! -> #REF! | L26: =#REF! -> #REF! | ... P26: =#REF! -> #REF! | Q26: =SUM(D26:P26) -> #REF!
B27: Value of your Start Up Loan | D27: =C18 -> 2500 | E27: n/a | F27: n/a | G27: n/a | H27: n/a | I27: n/a | J27: n/a | K27: n/a | L27: n/a | M27: n/a | N27: n/a | O27: n/a | P27: n/a | Q27: =SUM(D27:P27) -> 2500
B28: Other sources of cash or equity | D28: 0 | E28: 0 | F28: 0 | G28: 0 | H28: 0 | I28: 0 | J28: 0 | K28: 0 | L28: 0 | M28: 0 | N28: 0 | O28: 0 | P28: 0 | Q28: =SUM(D28:P28) -> 0
B29: Existing assets for business purposes | D29: 0 | E29: 0 | F29: 0 | G29: 0 | H29: 0 | I29: 0 | J29: 0 | K29: 0 | L29: 0 | M29: 0 | N29: 0 | O29: 0 | P29: 0 | Q29: =SUM(D29:P29) -> 0
B30: App sales | D30: 0 | E30: 0 | F30: 0 | G30: 0 | H30: 0 | I30: 0 | J30: 0 | K30: 0 | L30: 0 | M30: 0 | N30: 0 | O30: 0 | P30: 0 | Q30: =SUM(D30:P30) -> 0
B31: Enter other | D31: 0 | E31: 0 | F31: 0 | G31: 0 | H31: 0 | I31: 0 | J31: 0 | K31: 0 | L31: 0 | M31: 0 | N31: 0 | O31: 0 | P31: 0 | Q31: =SUM(D31:P31) -> 0
B32: Enter other | D32: 0 | E32: 0 | F32: 0 | G32: 0 | H32: 0 | I32: 0 | J32: 0 | K32: 0 | L32: 0 | M32: 0 | N32: 0 | O32: 0 | P32: 0 | Q32: =SUM(D32:P32) -> 0
B33: Enter other | D33: 0 | E33: 0 | F33: 0 | G33: 0 | H33: 0 | I33: 0 | J33: 0 | K33: 0 | L33: 0 | M33: 0 | N33: 0 | O33: 0 | P33: 0 | Q33: =SUM(D33:P33) -> 0
B34: Enter other | D34: 0 | E34: 0 | F34: 0 | G34: 0 | H34: 0 | I34: 0 | J34: 0 | K34: 0 | L34: 0 | M34: 0 | N34: 0 | O34: 0 | P34: 0 | Q34: =SUM(D34:P34) -> 0
B35: Enter other | D35: 0 | E35: 0 | F35: 0 | G35: 0 | H35: 0 | I35: 0 | J35: 0 | K35: 0 | L35: 0 | M35: 0 | N35: 0 | O35: 0 | P35: 0 | Q35: =SUM(D35:P35) -> 0
B36: Enter other | D36: 0 | E36: 0 | F36: 0 | G36: 0 | H36: 0 | I36: 0 | J36: 0 | K36: 0 | L36: 0 | M36: 0 | N36: 0 | O36: 0 | P36: 0 | Q36: =SUM(D36:P36) -> 0
B37: Total cash in-flows (A) | D37: =SUM(D26:D36) -> 2500 | E37: =SUM(E26:E36) -> #REF! | F37: =SUM(F26:F36) -> #REF! | G37: =SUM(G26:G36) -> #REF! | H37: =SUM(H26:H36) -> #REF! | I37: =SUM(I26:I36) -> #REF! | J37: =SUM(J26:J36) -> #REF! | K37: =SUM(K26:K36) -> #REF! | ... P37: =SUM(P26:P36) -> #REF! | Q37: =SUM(D37:P37) -> #REF!
E40: MONTHS
B41: Cash out-flows | C41: Description (as required) | D41: Starting point | E41: 1 | F41: 2 | G41: 3 | H41: 4 | I41: 5 | J41: 6 | K41: 7 | L41: 8 | M41: 9 | N41: 10 | O41: 11 | P41: 12 | Q41: TOTAL
B42: Total anticipated cost of sales | D42: 0 | E42: =#REF! -> #REF! | F42: =#REF! -> #REF! | G42: =#REF! -> #REF! | H42: =#REF! -> #REF! | I42: =#REF! -> #REF! | J42: =#REF! -> #REF! | K42: =#REF! -> #REF! | L42: =#REF! -> #REF! | ... P42: =#REF! -> #REF! | Q42: =SUM(D42:P42) -> #REF!
B43: Existing assets for business purposes | C43: 0 | D43: =SUM(D29) -> 0 | E43: 0 | F43: 0 | G43: 0 | H43: 0 | I43: 0 | J43: 0 | K43: 0 | L43: 0 | M43: 0 | N43: 0 | O43: 0 | P43: 0 | Q43: =SUM(D43:P43) -> 0
B44: Rent or premises costs | D44: 0 | E44: 0 | F44: 0 | G44: 0 | H44: 0 | I44: 0 | J44: 0 | K44: 0 | L44: 0 | M44: 0 | N44: 0 | O44: 0 | P44: 0 | Q44: =SUM(D44:P44) -> 0
B45: Business rates for your business premises | D45: 0 | E45: 0 | F45: 0 | G45: 0 | H45: 0 | I45: 0 | J45: 0 | K45: 0 | L45: 0 | M45: 0 | N45: 0 | O45: 0 | P45: 0 | Q45: =SUM(D45:P45) -> 0
B46: Utilities (gas, electricity, water) | D46: 0 | E46: 0 | F46: 0 | G46: 0 | H46: 0 | I46: 0 | J46: 0 | K46: 0 | L46: 0 | M46: 0 | N46: 0 | O46: 0 | P46: 0 | Q46: =SUM(D46:P46) -> 0
B47: Insurance | D47: 0 | E47: 0 | F47: 0 | G47: 0 | H47: 0 | I47: 0 | J47: 0 | K47: 0 | L47: 0 | M47: 0 | N47: 0 | O47: 0 | P47: 0 | Q47: =SUM(D47:P47) -> 0
B48: Telephone and internet | D48: 0 | E48: 0 | F48: 0 | G48: 0 | H48: 0 | I48: 0 | J48: 0 | K48: 0 | L48: 0 | M48: 0 | N48: 0 | O48: 0 | P48: 0 | Q48: =SUM(D48:P48) -> 0
B49: Marketing and advertising expenses | D49: 0 | E49: 0 | F49: 0 | G49: 0 | H49: 0 | I49: 0 | J49: 0 | K49: 0 | L49: 0 | M49: 0 | N49: 0 | O49: 0 | P49: 0 | Q49: =SUM(D49:P49) -> 0
B50: Vehicle running costs | D50: 0 | E50: 0 | F50: 0 | G50: 0 | H50: 0 | I50: 0 | J50: 0 | K50: 0 | L50: 0 | M50: 0 | N50: 0 | O50: 0 | P50: 0 | Q50: =SUM(D50:P50) -> 0
B51: Equipment purchase or leasing | D51: 200 | E51: 0 | F51: 0 | G51: 0 | H51: 0 | I51: 0 | J51: 0 | K51: 0 | L51: 0 | M51: 0 | N51: 0 | O51: 0 | P51: 0 | Q51: =SUM(D51:P51) -> 200
B52: Postage, printing, stationery | D52: 0 | E52: 0 | F52: 0 | G52: 0 | H52: 0 | I52: 0 | J52: 0 | K52: 0 | L52: 0 | M52: 0 | N52: 0 | O52: 0 | P52: 0 | Q52: =SUM(D52:P52) -> 0
B53: Transport and delivery | D53: 300 | E53: 0 | F53: 0 | G53: 0 | H53: 0 | I53: 0 | J53: 0 | K53: 0 | L53: 0 | M53: 0 | N53: 0 | O53: 0 | P53: 0 | Q53: =SUM(D53:P53) -> 300
...

Sheet 4 Cash Flow Forecast(CFF)
B3: 12-Month Cash Flow Forecast
B5: Name: | C5: =IF(ISBLANK(Guidance!$E$3),"",Guidance!$E$3)
B6: Company Name: | C6: =IF(ISBLANK(Guidance!$E$4),"",Guidance!$E$4)
B8: Your Cash Flow Forecast (CFF) is an estimate of the money you expect to bring in to and pay out of your business over the next 12-months. Importantly, it should reflect all of the activity you have described in your Business Plan. - Your CFF should show BUSINESS revenue and expenses only, not personal items; - Your CFF is FORWARD looking, reflecting future anticipated transactions into and out of your business; - You can input your loan amount and the term length (12-60months), which will autocalculate onto the CFF below; - You will be asked to choose a start month for your CFF; this should be the next month after you expect to receive the loan and should match up with the month you selected in your Sales Assumptions; - Remember, some of the information that you have created in your Sales Assumptions will auto-populate in your CFF tab. These cells are blue and you do not need to edit them; - Any assumptions you make regarding your cash in-flows and cash out-flows should be both realistic and supportable. If you're starting a new business, we suggest being conservative with the cash flows you enter for the early months of trading; - It's important that your CFF corresponds with all of the objectives and activities you have outlined in your Business Plan. For example, if you have detailed plans for a three-month marketing campaign in your Business Plan then the costs for running this campaign should be clearly visible in your CFF; - Your CFF is based on a future estimate and while these figures will no doubt change over that trading period, it is a good amount of time for you - and us - to see how sustainable your plans are; - There is a commentary box at the bottom, for which you can use to explain any of costings, which you think will be of use to your Business Adviser
O13: Key:
P14: These cells auto-calculate - you don't need to edit these.
P15: Insert your own text/numbers into these cells as relevant.
B18: Loan amount | C18: 2500
B19: Interest rate | C19: 0.06
B20: Loan term (months) | C20: 0
B21: Monthly repayment | C21: =IFERROR(PMT(C19/12,C20,C18)*-1,"")
B23: Select your starting month: | C23: May
E24: MONTHS
B25: Cash in-flows | C25: Description (as required) | D25: Starting point | E25: 1 | F25: 2 | G25: 3 | H25: 4 | I25: 5 | J25: 6 | K25: 7 | L25: 8 | M25: 9 | N25: 10 | O25: 11 | P25: 12 | Q25: TOTAL
B26: Total anticipated sales | D26: 0 | E26: =#REF! -> #REF! | F26: =#REF! -> #REF! | G26: =#REF! -> #REF! | H26: =#REF! -> #REF! | I26: =#REF! -> #REF! | J26: =#REF! -> #REF! | K26: =#REF! -> #REF! | L26: =#REF! -> #REF! | ... P26: =#REF! -> #REF! | Q26: =SUM(D26:P26) -> #REF!
B27: Value of your Start Up Loan | D27: =C18 -> 2500 | E27: n/a | F27: n/a | G27: n/a | H27: n/a | I27: n/a | J27: n/a | K27: n/a | L27: n/a | M27: n/a | N27: n/a | O27: n/a | P27: n/a | Q27: =SUM(D27:P27) -> 2500
B28: Other sources of cash or equity | D28: 0 | E28: 0 | F28: 0 | G28: 0 | H28: 0 | I28: 0 | J28: 0 | K28: 0 | L28: 0 | M28: 0 | N28: 0 | O28: 0 | P28: 0 | Q28: =SUM(D28:P28) -> 0
B29: Existing assets for business purposes | D29: 0 | E29: 0 | F29: 0 | G29: 0 | H29: 0 | I29: 0 | J29: 0 | K29: 0 | L29: 0 | M29: 0 | N29: 0 | O29: 0 | P29: 0 | Q29: =SUM(D29:P29) -> 0
B30: App sales | D30: 0 | E30: 0 | F30: 0 | G30: 0 | H30: 0 | I30: 0 | J30: 0 | K30: 0 | L30: 0 | M30: 0 | N30: 0 | O30: 0 | P30: 0 | Q30: =SUM(D30:P30) -> 0
B31: Enter other | D31: 0 | E31: 0 | F31: 0 | G31: 0 | H31: 0 | I31: 0 | J31: 0 | K31: 0 | L31: 0 | M31: 0 | N31: 0 | O31: 0 | P31: 0 | Q31: =SUM(D31:P31) -> 0
B32: Enter other | D32: 0 | E32: 0 | F32: 0 | G32: 0 | H32: 0 | I32: 0 | J32: 0 | K32: 0 | L32: 0 | M32: 0 | N32: 0 | O32: 0 | P32: 0 | Q32: =SUM(D32:P32) -> 0
B33: Enter other | D33: 0 | E33: 0 | F33: 0 | G33: 0 | H33: 0 | I33: 0 | J33: 0 | K33: 0 | L33: 0 | M33: 0 | N33: 0 | O33: 0 | P33: 0 | Q33: =SUM(D33:P33) -> 0
B34: Enter other | D34: 0 | E34: 0 | F34: 0 | G34: 0 | H34: 0 | I34: 0 | J34: 0 | K34: 0 | L34: 0 | M34: 0 | N34: 0 | O34: 0 | P34: 0 | Q34: =SUM(D34:P34) -> 0
B35: Enter other | D35: 0 | E35: 0 | F35: 0 | G35: 0 | H35: 0 | I35: 0 | J35: 0 | K35: 0 | L35: 0 | M35: 0 | N35: 0 | O35: 0 | P35: 0 | Q35: =SUM(D35:P35) -> 0
B36: Enter other | D36: 0 | E36: 0 | F36: 0 | G36: 0 | H36: 0 | I36: 0 | J36: 0 | K36: 0 | L36: 0 | M36: 0 | N36: 0 | O36: 0 | P36: 0 | Q36: =SUM(D36:P36) -> 0
B37: Total cash in-flows (A) | D37: =SUM(D26:D36) -> 2500 | E37: =SUM(E26:E36) -> #REF! | F37: =SUM(F26:F36) -> #REF! | G37: =SUM(G26:G36) -> #REF! | H37: =SUM(H26:H36) -> #REF! | I37: =SUM(I26:I36) -> #REF! | J37: =SUM(J26:J36) -> #REF! | K37: =SUM(K26:K36) -> #REF! | ... P37: =SUM(P26:P36) -> #REF! | Q37: =SUM(D37:P37) -> #REF!
E40: MONTHS
B41: Cash out-flows | C41: Description (as required) | D41: Starting point | E41: 1 | F41: 2 | G41: 3 | H41: 4 | I41: 5 | J41: 6 | K41: 7 | L41: 8 | M41: 9 | N41: 10 | O41: 11 | P41: 12 | Q41: TOTAL
B42: Total anticipated cost of sales | D42: 0 | E42: =#REF! -> #REF! | F42: =#REF! -> #REF! | G42: =#REF! -> #REF! | H42: =#REF! -> #REF! | I42: =#REF! -> #REF! | J42: =#REF! -> #REF! | K42: =#REF! -> #REF! | L42: =#REF! -> #REF! | ... P42: =#REF! -> #REF! | Q42: =SUM(D42:P42) -> #REF!
B43: Existing assets for business purposes | C43: 0 | D43: =SUM(D29) -> 0 | E43: 0 | F43: 0 | G43: 0 | H43: 0 | I43: 0 | J43: 0 | K43: 0 | L43: 0 | M43: 0 | N43: 0 | O43: 0 | P43: 0 | Q43: =SUM(D43:P43) -> 0
B44: Rent or premises costs | D44: 0 | E44: 0 | F44: 0 | G44: 0 | H44: 0 | I44: 0 | J44: 0 | K44: 0 | L44: 0 | M44: 0 | N44: 0 | O44: 0 | P44: 0 | Q44: =SUM(D44:P44) -> 0
B45: Business rates for your business premises | D45: 0 | E45: 0 | F45: 0 | G45: 0 | H45: 0 | I45: 0 | J45: 0 | K45: 0 | L45: 0 | M45: 0 | N45: 0 | O45: 0 | P45: 0 | Q45: =SUM(D45:P45) -> 0
B46: Utilities (gas, electricity, water) | D46: 0 | E46: 0 | F46: 0 | G46: 0 | H46: 0 | I46: 0 | J46: 0 | K46: 0 | L46: 0 | M46: 0 | N46: 0 | O46: 0 | P46: 0 | Q46: =SUM(D46:P46) -> 0
B47: Insurance | D47: 0 | E47: 0 | F47: 0 | G47: 0 | H47: 0 | I47: 0 | J47: 0 | K47: 0 | L47: 0 | M47: 0 | N47: 0 | O47: 0 | P47: 0 | Q47: =SUM(D47:P47) -> 0
B48: Telephone and internet | D48: 0 | E48: 0 | F48: 0 | G48: 0 | H48: 0 | I48: 0 | J48: 0 | K48: 0 | L48: 0 | M48: 0 | N48: 0 | O48: 0 | P48: 0 | Q48: =SUM(D48:P48) -> 0
B49: Marketing and advertising expenses | D49: 0 | E49: 0 | F49: 0 | G49: 0 | H49: 0 | I49: 0 | J49: 0 | K49: 0 | L49: 0 | M49: 0 | N49: 0 | O49: 0 | P49: 0 | Q49: =SUM(D49:P49) -> 0
B50: Vehicle running costs | D50: 0 | E50: 0 | F50: 0 | G50: 0 | H50: 0 | I50: 0 | J50: 0 | K50: 0 | L50: 0 | M50: 0 | N50: 0 | O50: 0 | P50: 0 | Q50: =SUM(D50:P50) -> 0
B51: Equipment purchase or leasing | D51: 200 | E51: 0 | F51: 0 | G51: 0 | H51: 0 | I51: 0 | J51: 0 | K51: 0 | L51: 0 | M51: 0 | N51: 0 | O51: 0 | P51: 0 | Q51: =SUM(D51:P51) -> 200
B52: Postage, printing, stationery | D52: 0 | E52: 0 | F52: 0 | G52: 0 | H52: 0 | I52: 0 | J52: 0 | K52: 0 | L52: 0 | M52: 0 | N52: 0 | O52: 0 | P52: 0 | Q52: =SUM(D52:P52) -> 0
B53: Transport and delivery | D53: 300 | E53: 0 | F53: 0 | G53: 0 | H53: 0 | I53: 0 | J53: 0 | K53: 0 | L53: 0 | M53: 0 | N53: 0 | O53: 0 | P53: 0 | Q53: =SUM(D53:P53) -> 300
...

Sheet 1 Actual Cash Flows
B3: ACTUAL CASH FLOWS: SIX-MONTHS
B5: Enter your full name | I5: Key:
B6: Enter your company name | J6: These cells auto-calculate and are locked so you can't edit them.
B7: Enter date | J7: Insert your own text/numbers into these cells as relevant.
B10: Select your starting month:
E11: MONTHS
B12: Cash in-flows | C12: Description (as required) | D12: Starting point | E12: 1 | F12: 2 | G12: 3 | H12: 4 | I12: 5 | J12: 6 | K12: TOTAL
B13: Total sales revenue | D13: 0 | E13: 0 | F13: 0 | G13: 0 | H13: 0 | I13: 0 | J13: 0 | K13: =SUM(D13:J13) -> 0
B14: Sources of investment | D14: 0 | E14: 0 | F14: 0 | G14: 0 | H14: 0 | I14: 0 | J14: 0 | K14: =SUM(D14:J14) -> 0
B15: Debt-based finance | D15: 0 | E15: 0 | F15: 0 | G15: 0 | H15: 0 | I15: 0 | J15: 0 | K15: =SUM(D15:J15) -> 0
B16: Enter other | D16: 0 | E16: 0 | F16: 0 | G16: 0 | H16: 0 | I16: 0 | J16: 0 | K16: =SUM(D16:J16) -> 0
B17: Enter other | D17: 0 | E17: 0 | F17: 0 | G17: 0 | H17: 0 | I17: 0 | J17: 0 | K17: =SUM(D17:J17) -> 0
B18: Enter other | D18: 0 | E18: 0 | F18: 0 | G18: 0 | H18: 0 | I18: 0 | J18: 0 | K18: =SUM(D18:J18) -> 0
B19: Total cash in-flows (A) | D19: =SUM(D13:D18) -> 0 | E19: =SUM(E13:E18) -> 0 | F19: =SUM(F13:F18) -> 0 | G19: =SUM(G13:G18) -> 0 | H19: =SUM(H13:H18) -> 0 | I19: =SUM(I13:I18) -> 0 | J19: =SUM(J13:J18) -> 0 | K19: =SUM(D19:J19) -> 0
E21: MONTHS
B22: Cash out-flows | C22: Description (as required) | D22: Starting point | E22: 1 | F22: 2 | G22: 3 | H22: 4 | I22: 5 | J22: 6 | K22: TOTAL
B23: Cost of sales | D23: 0 | E23: 0 | F23: 0 | G23: 0 | H23: 0 | I23: 0 | J23: 0 | K23: =SUM(D23:J23) -> 0
B24: Rent or premises costs | D24: 0 | E24: 0 | F24: 0 | G24: 0 | H24: 0 | I24: 0 | J24: 0 | K24: =SUM(D24:J24) -> 0
B25: Business rates for your business premises | D25: 0 | E25: 0 | F25: 0 | G25: 0 | H25: 0 | I25: 0 | J25: 0 | K25: =SUM(D25:J25) -> 0
B26: Utilities (gas, electricity, water) | D26: 0 | E26: 0 | F26: 0 | G26: 0 | H26: 0 | I26: 0 | J26: 0 | K26: =SUM(D26:J26) -> 0
B27: Insurance | D27: 0 | E27: 0 | F27: 0 | G27: 0 | H27: 0 | I27: 0 | J27: 0 | K27: =SUM(D27:J27) -> 0
B28: Telephone and internet | D28: 0 | E28: 0 | F28: 0 | G28: 0 | H28: 0 | I28: 0 | J28: 0 | K28: =SUM(D28:J28) -> 0
B29: Marketing and advertising expenses | D29: 0 | E29: 0 | F29: 0 | G29: 0 | H29: 0 | I29: 0 | J29: 0 | K29: =SUM(D29:J29) -> 0
B30: Vehicle running costs | D30: 0 | E30: 0 | F30: 0 | G30: 0 | H30: 0 | I30: 0 | J30: 0 | K30: =SUM(D30:J30) -> 0
B31: Equipment purchase or leasing | D31: 0 | E31: 0 | F31: 0 | G31: 0 | H31: 0 | I31: 0 | J31: 0 | K31: =SUM(D31:J31) -> 0
B32: Postage, printing, stationery | D32: 0 | E32: 0 | F32: 0 | G32: 0 | H32: 0 | I32: 0 | J32: 0 | K32: =SUM(D32:J32) -> 0
B33: Transport and delivery | D33: 0 | E33: 0 | F33: 0 | G33: 0 | H33: 0 | I33: 0 | J33: 0 | K33: =SUM(D33:J33) -> 0
B34: Professional fees (legal, accounting etc.) | D34: 0 | E34: 0 | F34: 0 | G34: 0 | H34: 0 | I34: 0 | J34: 0 | K34: =SUM(D34:J34) -> 0
B35: Your salary | D35: n/a | E35: 0 | F35: 0 | G35: 0 | H35: 0 | I35: 0 | J35: 0 | K35: =SUM(D35:J35) -> 0
B36: Staff costs | D36: 0 | E36: 0 | F36: 0 | G36: 0 | H36: 0 | I36: 0 | J36: 0 | K36: =SUM(D36:J36) -> 0
B37: Start Up Loan monthly repayment* | D37: n/a | E37: 0 | F37: =E37 -> 0 | G37: =E37 -> 0 | H37: =E37 -> 0 | I37: =E37 -> 0 | J37: =E37 -> 0 | K37: =SUM(D37:J37) -> 0
B38: Enter other | D38: 0 | E38: 0 | F38: 0 | G38: 0 | H38: 0 | I38: 0 | J38: 0 | K38: =SUM(D38:J38) -> 0
B39: Enter other | D39: 0 | E39: 0 | F39: 0 | G39: 0 | H39: 0 | I39: 0 | J39: 0 | K39: =SUM(D39:J39) -> 0
B40: Enter other | D40: 0 | E40: 0 | F40: 0 | G40: 0 | H40: 0 | I40: 0 | J40: 0 | K40: =SUM(D40:J40) -> 0
B41: Enter other | D41: 0 | E41: 0 | F41: 0 | G41: 0 | H41: 0 | I41: 0 | J41: 0 | K41: =SUM(D41:J41) -> 0
B42: Enter other | D42: 0 | E42: 0 | F42: 0 | G42: 0 | H42: 0 | I42: 0 | J42: 0 | K42: =SUM(D42:J42) -> 0
B43: Total cash out-flows (B) | D43: =SUM(D23:D42) -> 0 | E43: =SUM(E23:E42) -> 0 | F43: =SUM(F23:F42) -> 0 | G43: =SUM(G23:G42) -> 0 | H43: =SUM(H23:H42) -> 0 | I43: =SUM(I23:I42) -> 0 | J43: =SUM(J23:J42) -> 0 | K43: =SUM(D43:J43) -> 0
C45: Your net cash flow (A-B) | D45: =D19-D43 -> 0 | E45: =E19-E43 -> 0 | F45: =F19-F43 -> 0 | G45: =G19-G43 -> 0 | H45: =H19-H43 -> 0 | I45: =I19-I43 -> 0 | J45: =J19-J43 -> 0 | K45: =K19-K43 -> 0
C47: Your monthly opening business bank account balance | D47: 0 | E47: =D49 -> 0 | F47: =E49 -> 0 | G47: =F49 -> 0 | H47: =G49 -> 0 | I47: =H49 -> 0 | J47: =I49 -> 0 | K47: =J49 -> 0
C49: Your closing cash position | D49: =D45+D47 -> 0 | E49: =E45+E47 -> 0 | F49: =F45+F47 -> 0 | G49: =G45+G47 -> 0 | H49: =H45+H47 -> 0 | I49: =I45+I47 -> 0 | J49: =J45+J47 -> 0 | K49: =K47 -> 0
...

Sheet Excel Tips
D3: Name: | E3: =IF(ISBLANK(Guidance!$E$3),"",Guidance!$E$3)
D4: Company Name: | E4: =IF(ISBLANK(Guidance!$E$4),"",Guidance!$E$4)
D5: Application Number: | E5: =IF(ISBLANK(Guidance!#REF!),"",Guidance!#REF!) -> #REF!
B7: Excel Tips
B9: * | C9: If you need to go to the next line in a cell or create another bullet point in the same cell, press and hold the Alt key and click the Enter key once (Control key, option key and return key for mac users). This will tab down to the next line but you will remain in the same cell. To save the changes you have made to the cell, press Enter once you are finished. Do not press Esc as this will delete your changes.
B10: * | C10: If you need to edit a cell without deleting any of the text you have already typed in, first select the cell and click in the formula bar (shown in screenshot below)
B25: * | C25: Wherever you click in the function box, that is where your curser will appear and you will be able to add text. Please see an example below.
B37: * | C37: We have tried to size the answer cells appropriately so you don't have to make any changes. If, however, the paragraph you are writing is long and the text begins to go outside of the cell boundaries, expand the formula bar by hovering over the bottom line of the formula bar until the double headed arrow appears. Click and drag the arrow down and the formular bar will be expanded as shown below. Click Enter once you have completed the paragraph.
B52: * | C52: Once you have expanded the formula bar and you are happy with the content of the cell, expand the row by clicking and dragging the row separator as shown below. Press enter to save your changes in the cell.
B63: * | C63: To view comments on the spreadsheet, click review at the top middle of the ribbon. Next, click show comments. You should be able to move through the comments by clicking next comment or previous comment.
